Workbook
Name OLE_LINK1: 'P&L Отчет'!#REF!
Name База_цена: Продажи!$L$2
Name Срез_Станция_ДО: #N/A
Name Срез_Станция_ОТ: #N/A
Name Срез_Тип_пассажира: #N/A
Name Срез_Тип_полки: #N/A

Sheet Dashboard
A1: «Аналитическая модель рейса: Москва — Ростов-на-Дону». (на примере расчёта одного плацкартного вагона)
A5: Выручка | D5: ='P&L Отчет'!C6 -> 72487.75 | AX5: {="Точка роста (Макс. спрос): участок " & INDEX(Справочник!$B$2:$B$31, MATCH(MAX(Аналитика!$B$57:$AD$57), Аналитика!$B$57:$AD$57, 0)) & " — " & INDEX(Справочник!$B$2:$B$31, MATCH(MAX(Аналитика!$B$57:$AD$57), Аналитика!$B$57:$AD$57, 0) + 1) & " (загрузка " & TEXT(MAX(Аналитика!$B$57:$AD$57)/54, "0%") & ")"} -> Точка роста (Макс. спрос): участок Мичуринск-Вор. — Грязи-Воронежские (загрузка 28%)
A6: Затраты | D6: ='P&L Отчет'!C15 -> 66900 | AI6: Рентабельность | AL6: ='P&L Отчет'!C22 -> 0.077085439
A7: Чистая прибыль | D7: ='P&L Отчет'!C19 -> 5587.75 | AI7: Загрузка (Load Factor) | AL7: ='P&L Отчет'!C23 -> 0.23371648 | AX7: {="Зона риска (Мин. спрос): участок " & INDEX(Справочник!$B$2:$B$31, MATCH(MIN(Аналитика!$B$57:$AD$57), Аналитика!$B$57:$AD$57, 0)) & " — " & INDEX(Справочник!$B$2:$B$31, MATCH(MIN(Аналитика!$B$57:$AD$57), Аналитика!$B$57:$AD$57, 0) + 1) & " (загрузка " & TEXT(MIN(Аналитика!$B$57:$AD$57)/54, "0%") & ")"} -> Зона риска (Мин. спрос): участок Шахтная — Каменоломни (загрузка 19%)

Sheet Продажи
A1: ID билета | B1: Место | C1: Станция ОТ | D1: Станция ДО | E1: Индекс ОТ | F1: Индекс ДО | G1: Тип пассажира | H1: Тип полки | I1: Базовая цена, руб | J1: Сумма скидки льготникам, руб | K1: Сумма скидки тип-места, руб2 | L1: Цена, ₽ | N1: Статус места | O1: Тип полки | P1: № места | Q1: Наличие полного купе | R1: Выбор станции маршрута | S1: Наименование станций | T1: № зоны
A2: =IF(ISBLANK(Sales[[#This Row],[Место]]),"",CONCATENATE("T-00"&ROW()-1)) -> T-001 | B2: 1 | C2: Москва (Казанский) | D2: Ростов-Главный | E2: =IFERROR(_xlfn.XLOOKUP(Sales[[#This Row],[Станция ОТ]],Справочник_станций_и_сборов[Станция (остановка)],Справочник_станций_и_сборов[ID]),"") -> 1 | F2: =IFERROR(_xlfn.XLOOKUP(Sales[[#This Row],[Станция ДО]],Справочник_станций_и_сборов[Станция (остановка)],Справочник_станций_и_сборов[ID]),"") -> 30 | G2: Полный | H2: =IF(ISBLANK(Sales[[#This Row],[Место]]),"",IF(Sales[[#This Row],[Место]]>36, IF(MOD(Sales[[#This Row],[Место]],2)=0, "Верхнее боковое место", "Нижнее боковое место"), IF(MOD(Sales[[#This Row],[Место]],2)=0, "Верхнее место", "Нижнее место"))) -> Нижнее место | I2: =IFERROR(((_xlfn.XLOOKUP(Sales[[#This Row],[Станция ДО]],Справочник_станций_и_сборов[Станция (остановка)],Справочник_станций_и_сборов[Расстояние от Мск (км)],)-_xlfn.XLOOKUP(Sales[[#This Row],[Станция ОТ]],Справочник_станций_и_сборов[Станция (остановка)],Справочник_станций_и_сборов[Расстояние от Мск (км)],))*Справочник!$Q$3+Справочник!$Q$2),"") -> 5105 | J2: =IFERROR(Sales[[#This Row],[Базовая цена, руб]] * _xlfn.XLOOKUP(Sales[[#This Row],[Тип пассажира]],Тип_пассажира[Наименование],Тип_пассажира[Цена]), "") -> 0 | K2: =IFERROR(Sales[[#This Row],[Базовая цена, руб]] * VALUE(_xlfn.XLOOKUP(Sales[[#This Row],[Тип полки]], Тариф_полок[Тип полки], Тариф_полок[Коэф-нт цены], 1)),"") -> 0 | L2: =IFERROR((Sales[[#This Row],[Базовая цена, руб]]-Sales[[#This Row],[Сумма скидки льготникам, руб]])-Sales[[#This Row],[Сумма скидки тип-места, руб2]],"") -> 5105 | N2: =IF(ISBLANK(P2),"","Свободно") -> Свободно | O2: =IF(ISBLANK(P2),"",IF(P2>36, IF(MOD(P2,2)=0, "Верхнее боковое место", "Нижнее боковое место"), IF(MOD(P2,2)=0, "Верхнее место", "Нижнее место"))) -> Нижнее место | P2: {=_xlfn._xlws.FILTER(Аналитика!A3:A56, Аналитика!AF3:AF56="Свободно", "Мест нет")} -> 15 | Q2: =IFERROR(VLOOKUP(P2,Аналитика!A3:AH56,34,0),"") -> Частично | S2: Москва (Казанский) | T2: =VALUE(_xlfn.XLOOKUP(S2,Справочник_станций_и_сборов[Станция (остановка)],Справочник_станций_и_сборов[ID])) -> 1
A3: =IF(ISBLANK(Sales[[#This Row],[Место]]),"",CONCATENATE("T-00"&ROW()-1)) -> T-002 | B3: 2 | C3: Москва (Казанский) | D3: Воронеж 1 | E3: =IFERROR(_xlfn.XLOOKUP(Sales[[#This Row],[Станция ОТ]],Справочник_станций_и_сборов[Станция (остановка)],Справочник_станций_и_сборов[ID]),"") -> 1 | F3: =IFERROR(_xlfn.XLOOKUP(Sales[[#This Row],[Станция ДО]],Справочник_станций_и_сборов[Станция (остановка)],Справочник_станций_и_сборов[ID]),"") -> 6 | G3: Полный | H3: =IF(ISBLANK(Sales[[#This Row],[Место]]),"",IF(Sales[[#This Row],[Место]]>36, IF(MOD(Sales[[#This Row],[Место]],2)=0, "Верхнее боковое место", "Нижнее боковое место"), IF(MOD(Sales[[#This Row],[Место]],2)=0, "Верхнее место", "Нижнее место"))) -> Верхнее место | I3: =IFERROR(((_xlfn.XLOOKUP(Sales[[#This Row],[Станция ДО]],Справочник_станций_и_сборов[Станция (остановка)],Справочник_станций_и_сборов[Расстояние от Мск (км)],)-_xlfn.XLOOKUP(Sales[[#This Row],[Станция ОТ]],Справочник_станций_и_сборов[Станция (остановка)],Справочник_станций_и_сборов[Расстояние от Мск (км)],))*Справочник!$Q$3+Справочник!$Q$2),"") -> 2861.5 | J3: =IFERROR(Sales[[#This Row],[Базовая цена, руб]] * _xlfn.XLOOKUP(Sales[[#This Row],[Тип пассажира]],Тип_пассажира[Наименование],Тип_пассажира[Цена]), "") -> 0 | K3: =IFERROR(Sales[[#This Row],[Базовая цена, руб]] * VALUE(_xlfn.XLOOKUP(Sales[[#This Row],[Тип полки]], Тариф_полок[Тип полки], Тариф_полок[Коэф-нт цены], 1)),"") -> 286.15 | L3: =IFERROR((Sales[[#This Row],[Базовая цена, руб]]-Sales[[#This Row],[Сумма скидки льготникам, руб]])-Sales[[#This Row],[Сумма скидки тип-места, руб2]],"") -> 2575.35 | N3: =IF(ISBLANK(P3),"","Свободно") -> Свободно | O3: =IF(ISBLANK(P3),"",IF(P3>36, IF(MOD(P3,2)=0, "Верхнее боковое место", "Нижнее боковое место"), IF(MOD(P3,2)=0, "Верхнее место", "Нижнее место"))) -> Верхнее место | P3: 16 | Q3: =IFERROR(VLOOKUP(P3,Аналитика!A4:AH57,34,0),"") -> Частично | S3: Рязань 2 | T3: =VALUE(_xlfn.XLOOKUP(S3,Справочник_станций_и_сборов[Станция (остановка)],Справочник_станций_и_сборов[ID])) -> 2
A4: =IF(ISBLANK(Sales[[#This Row],[Место]]),"",CONCATENATE("T-00"&ROW()-1)) -> T-003 | B4: 2 | C4: Воронеж 1 | D4: Ростов-Главный | E4: =IFERROR(_xlfn.XLOOKUP(Sales[[#This Row],[Станция ОТ]],Справочник_станций_и_сборов[Станция (остановка)],Справочник_станций_и_сборов[ID]),"") -> 6 | F4: =IFERROR(_xlfn.XLOOKUP(Sales[[#This Row],[Станция ДО]],Справочник_станций_и_сборов[Станция (остановка)],Справочник_станций_и_сборов[ID]),"") -> 30 | G4: Полный | H4: =IF(ISBLANK(Sales[[#This Row],[Место]]),"",IF(Sales[[#This Row],[Место]]>36, IF(MOD(Sales[[#This Row],[Место]],2)=0, "Верхнее боковое место", "Нижнее боковое место"), IF(MOD(Sales[[#This Row],[Место]],2)=0, "Верхнее место", "Нижнее место"))) -> Верхнее место | I4: =IFERROR(((_xlfn.XLOOKUP(Sales[[#This Row],[Станция ДО]],Справочник_станций_и_сборов[Станция (остановка)],Справочник_станций_и_сборов[Расстояние от Мск (км)],)-_xlfn.XLOOKUP(Sales[[#This Row],[Станция ОТ]],Справочник_станций_и_сборов[Станция (остановка)],Справочник_станций_и_сборов[Расстояние от Мск (км)],))*Справочник!$Q$3+Справочник!$Q$2),"") -> 3043.5 | J4: =IFERROR(Sales[[#This Row],[Базовая цена, руб]] * _xlfn.XLOOKUP(Sales[[#This Row],[Тип пассажира]],Тип_пассажира[Наименование],Тип_пассажира[Цена]), "") -> 0 | K4: =IFERROR(Sales[[#This Row],[Базовая цена, руб]] * VALUE(_xlfn.XLOOKUP(Sales[[#This Row],[Тип полки]], Тариф_полок[Тип полки], Тариф_полок[Коэф-нт цены], 1)),"") -> 304.35 | L4: =IFERROR((Sales[[#This Row],[Базовая цена, руб]]-Sales[[#This Row],[Сумма скидки льготникам, руб]])-Sales[[#This Row],[Сумма скидки тип-места, руб2]],"") -> 2739.15 | N4: =IF(ISBLANK(P4),"","Свободно") -> Свободно | O4: =IF(ISBLANK(P4),"",IF(P4>36, IF(MOD(P4,2)=0, "Верхнее боковое место", "Нижнее боковое место"), IF(MOD(P4,2)=0, "Верхнее место", "Нижнее место"))) -> Нижнее место | P4: 17 | Q4: =IFERROR(VLOOKUP(P4,Аналитика!A5:AH58,34,0),"") -> Частично | S4: Ряжск 1 | T4: =VALUE(_xlfn.XLOOKUP(S4,Справочник_станций_и_сборов[Станция (остановка)],Справочник_станций_и_сборов[ID])) -> 3
A5: =IF(ISBLANK(Sales[[#This Row],[Место]]),"",CONCATENATE("T-00"&ROW()-1)) -> T-004 | B5: 3 | C5: Москва (Казанский) | D5: Мичуринск-Вор. | E5: =IFERROR(_xlfn.XLOOKUP(Sales[[#This Row],[Станция ОТ]],Справочник_станций_и_сборов[Станция (остановка)],Справочник_станций_и_сборов[ID]),"") -> 1 | F5: =IFERROR(_xlfn.XLOOKUP(Sales[[#This Row],[Станция ДО]],Справочник_станций_и_сборов[Станция (остановка)],Справочник_станций_и_сборов[ID]),"") -> 4 | G5: Полный | H5: =IF(ISBLANK(Sales[[#This Row],[Место]]),"",IF(Sales[[#This Row],[Место]]>36, IF(MOD(Sales[[#This Row],[Место]],2)=0, "Верхнее боковое место", "Нижнее боковое место"), IF(MOD(Sales[[#This Row],[Место]],2)=0, "Верхнее место", "Нижнее место"))) -> Нижнее место | I5: =IFERROR(((_xlfn.XLOOKUP(Sales[[#This Row],[Станция ДО]],Справочник_станций_и_сборов[Станция (остановка)],Справочник_станций_и_сборов[Расстояние от Мск (км)],)-_xlfn.XLOOKUP(Sales[[#This Row],[Станция ОТ]],Справочник_станций_и_сборов[Станция (остановка)],Справочник_станций_и_сборов[Расстояние от Мск (км)],))*Справочник!$Q$3+Справочник!$Q$2),"") -> 2235 | J5: =IFERROR(Sales[[#This Row],[Базовая цена, руб]] * _xlfn.XLOOKUP(Sales[[#This Row],[Тип пассажира]],Тип_пассажира[Наименование],Тип_пассажира[Цена]), "") -> 0 | K5: =IFERROR(Sales[[#This Row],[Базовая цена, руб]] * VALUE(_xlfn.XLOOKUP(Sales[[#This Row],[Тип полки]], Тариф_полок[Тип полки], Тариф_полок[Коэф-нт цены], 1)),"") -> 0 | L5: =IFERROR((Sales[[#This Row],[Базовая цена, руб]]-Sales[[#This Row],[Сумма скидки льготникам, руб]])-Sales[[#This Row],[Сумма скидки тип-места, руб2]],"") -> 2235 | N5: =IF(ISBLANK(P5),"","Свободно") -> Свободно | O5: =IF(ISBLANK(P5),"",IF(P5>36, IF(MOD(P5,2)=0, "Верхнее боковое место", "Нижнее боковое место"), IF(MOD(P5,2)=0, "Верхнее место", "Нижнее место"))) -> Нижнее место | P5: 19 | Q5: =IFERROR(VLOOKUP(P5,Аналитика!A6:AH59,34,0),"") -> Частично | R5: Станция отправления | S5: Мичуринск-Вор. | T5: =VALUE(_xlfn.XLOOKUP(S5,Справочник_станций_и_сборов[Станция (остановка)],Справочник_станций_и_сборов[ID])) -> 4
A6: =IF(ISBLANK(Sales[[#This Row],[Место]]),"",CONCATENATE("T-00"&ROW()-1)) -> T-005 | B6: 3 | C6: Мичуринск-Вор. | D6: Лиски | E6: =IFERROR(_xlfn.XLOOKUP(Sales[[#This Row],[Станция ОТ]],Справочник_станций_и_сборов[Станция (остановка)],Справочник_станций_и_сборов[ID]),"") -> 4 | F6: =IFERROR(_xlfn.XLOOKUP(Sales[[#This Row],[Станция ДО]],Справочник_станций_и_сборов[Станция (остановка)],Справочник_станций_и_сборов[ID]),"") -> 7 | G6: Полный | H6: =IF(ISBLANK(Sales[[#This Row],[Место]]),"",IF(Sales[[#This Row],[Место]]>36, IF(MOD(Sales[[#This Row],[Место]],2)=0, "Верхнее боковое место", "Нижнее боковое место"), IF(MOD(Sales[[#This Row],[Место]],2)=0, "Верхнее место", "Нижнее место"))) -> Нижнее место | I6: =IFERROR(((_xlfn.XLOOKUP(Sales[[#This Row],[Станция ДО]],Справочник_станций_и_сборов[Станция (остановка)],Справочник_станций_и_сборов[Расстояние от Мск (км)],)-_xlfn.XLOOKUP(Sales[[#This Row],[Станция ОТ]],Справочник_станций_и_сборов[Станция (остановка)],Справочник_станций_и_сборов[Расстояние от Мск (км)],))*Справочник!$Q$3+Справочник!$Q$2),"") -> 1769.5 | J6: =IFERROR(Sales[[#This Row],[Базовая цена, руб]] * _xlfn.XLOOKUP(Sales[[#This Row],[Тип пассажира]],Тип_пассажира[Наименование],Тип_пассажира[Цена]), "") -> 0 | K6: =IFERROR(Sales[[#This Row],[Базовая цена, руб]] * VALUE(_xlfn.XLOOKUP(Sales[[#This Row],[Тип полки]], Тариф_полок[Тип полки], Тариф_полок[Коэф-нт цены], 1)),"") -> 0 | L6: =IFERROR((Sales[[#This Row],[Базовая цена, руб]]-Sales[[#This Row],[Сумма скидки льготникам, руб]])-Sales[[#This Row],[Сумма скидки тип-места, руб2]],"") -> 1769.5 | N6: =IF(ISBLANK(P6),"","Свободно") -> Свободно | O6: =IF(ISBLANK(P6),"",IF(P6>36, IF(MOD(P6,2)=0, "Верхнее боковое место", "Нижнее боковое место"), IF(MOD(P6,2)=0, "Верхнее место", "Нижнее место"))) -> Верхнее место | P6: 20 | Q6: =IFERROR(VLOOKUP(P6,Аналитика!A7:AH60,34,0),"") -> Частично | S6: Грязи-Воронежские | T6: =VALUE(_xlfn.XLOOKUP(S6,Справочник_станций_и_сборов[Станция (остановка)],Справочник_станций_и_сборов[ID])) -> 5
A7: =IF(ISBLANK(Sales[[#This Row],[Место]]),"",CONCATENATE("T-00"&ROW()-1)) -> T-006 | B7: 3 | C7: Россошь | D7: Ростов-Главный | E7: =IFERROR(_xlfn.XLOOKUP(Sales[[#This Row],[Станция ОТ]],Справочник_станций_и_сборов[Станция (остановка)],Справочник_станций_и_сборов[ID]),"") -> 12 | F7: =IFERROR(_xlfn.XLOOKUP(Sales[[#This Row],[Станция ДО]],Справочник_станций_и_сборов[Станция (остановка)],Справочник_станций_и_сборов[ID]),"") -> 30 | G7: Полный | H7: =IF(ISBLANK(Sales[[#This Row],[Место]]),"",IF(Sales[[#This Row],[Место]]>36, IF(MOD(Sales[[#This Row],[Место]],2)=0, "Верхнее боковое место", "Нижнее боковое место"), IF(MOD(Sales[[#This Row],[Место]],2)=0, "Верхнее место", "Нижнее место"))) -> Нижнее место | I7: =IFERROR(((_xlfn.XLOOKUP(Sales[[#This Row],[Станция ДО]],Справочник_станций_и_сборов[Станция (остановка)],Справочник_станций_и_сборов[Расстояние от Мск (км)],)-_xlfn.XLOOKUP(Sales[[#This Row],[Станция ОТ]],Справочник_станций_и_сборов[Станция (остановка)],Справочник_станций_и_сборов[Расстояние от Мск (км)],))*Справочник!$Q$3+Справочник!$Q$2),"") -> 2224.5 | J7: =IFERROR(Sales[[#This Row],[Базовая цена, руб]] * _xlfn.XLOOKUP(Sales[[#This Row],[Тип пассажира]],Тип_пассажира[Наименование],Тип_пассажира[Цена]), "") -> 0 | K7: =IFERROR(Sales[[#This Row],[Базовая цена, руб]] * VALUE(_xlfn.XLOOKUP(Sales[[#This Row],[Тип полки]], Тариф_полок[Тип полки], Тариф_полок[Коэф-нт цены], 1)),"") -> 0 | L7: =IFERROR((Sales[[#This Row],[Базовая цена, руб]]-Sales[[#This Row],[Сумма скидки льготникам, руб]])-Sales[[#This Row],[Сумма скидки тип-места, руб2]],"") -> 2224.5 | N7: =IF(ISBLANK(P7),"","Свободно") -> Свободно | O7: =IF(ISBLANK(P7),"",IF(P7>36, IF(MOD(P7,2)=0, "Верхнее боковое место", "Нижнее боковое место"), IF(MOD(P7,2)=0, "Верхнее место", "Нижнее место"))) -> Нижнее место | P7: 21 | Q7: =IFERROR(VLOOKUP(P7,Аналитика!A8:AH61,34,0),"") -> Целое купе/отсек | S7: Воронеж 1 | T7: =VALUE(_xlfn.XLOOKUP(S7,Справочник_станций_и_сборов[Станция (остановка)],Справочник_станций_и_сборов[ID])) -> 6
A8: =IF(ISBLANK(Sales[[#This Row],[Место]]),"",CONCATENATE("T-00"&ROW()-1)) -> T-007 | B8: 4 | C8: Рязань 2 | D8: Каменская | E8: =IFERROR(_xlfn.XLOOKUP(Sales[[#This Row],[Станция ОТ]],Справочник_станций_и_сборов[Станция (остановка)],Справочник_станций_и_сборов[ID]),"") -> 2 | F8: =IFERROR(_xlfn.XLOOKUP(Sales[[#This Row],[Станция ДО]],Справочник_станций_и_сборов[Станция (остановка)],Справочник_станций_и_сборов[ID]),"") -> 19 | G8: Полный | H8: =IF(ISBLANK(Sales[[#This Row],[Место]]),"",IF(Sales[[#This Row],[Место]]>36, IF(MOD(Sales[[#This Row],[Место]],2)=0, "Верхнее боковое место", "Нижнее боковое место"), IF(MOD(Sales[[#This Row],[Место]],2)=0, "Верхнее место", "Нижнее место"))) -> Верхнее место | I8: =IFERROR(((_xlfn.XLOOKUP(Sales[[#This Row],[Станция ДО]],Справочник_станций_и_сборов[Станция (остановка)],Справочник_станций_и_сборов[Расстояние от Мск (км)],)-_xlfn.XLOOKUP(Sales[[#This Row],[Станция ОТ]],Справочник_станций_и_сборов[Станция (остановка)],Справочник_станций_и_сборов[Расстояние от Мск (км)],))*Справочник!$Q$3+Справочник!$Q$2),"") -> 3834.5 | J8: =IFERROR(Sales[[#This Row],[Базовая цена, руб]] * _xlfn.XLOOKUP(Sales[[#This Row],[Тип пассажира]],Тип_пассажира[Наименование],Тип_пассажира[Цена]), "") -> 0 | K8: =IFERROR(Sales[[#This Row],[Базовая цена, руб]] * VALUE(_xlfn.XLOOKUP(Sales[[#This Row],[Тип полки]], Тариф_полок[Тип полки], Тариф_полок[Коэф-нт цены], 1)),"") -> 383.45 | L8: =IFERROR((Sales[[#This Row],[Базовая цена, руб]]-Sales[[#This Row],[Сумма скидки льготникам, руб]])-Sales[[#This Row],[Сумма скидки тип-места, руб2]],"") -> 3451.05 | N8: =IF(ISBLANK(P8),"","Свободно") -> Свободно | O8: =IF(ISBLANK(P8),"",IF(P8>36, IF(MOD(P8,2)=0, "Верхнее боковое место", "Нижнее боковое место"), IF(MOD(P8,2)=0, "Верхнее место", "Нижнее место"))) -> Верхнее место | P8: 22 | Q8: =IFERROR(VLOOKUP(P8,Аналитика!A9:AH62,34,0),"") -> Целое купе/отсек | S8: Лиски | T8: =VALUE(_xlfn.XLOOKUP(S8,Справочник_станций_и_сборов[Станция (остановка)],Справочник_станций_и_сборов[ID])) -> 7
A9: =IF(ISBLANK(Sales[[#This Row],[Место]]),"",CONCATENATE("T-00"&ROW()-1)) -> T-008 | B9: 18 | C9: Воронеж 1 | D9: Ростов-Главный | E9: =IFERROR(_xlfn.XLOOKUP(Sales[[#This Row],[Станция ОТ]],Справочник_станций_и_сборов[Станция (остановка)],Справочник_станций_и_сборов[ID]),"") -> 6 | F9: =IFERROR(_xlfn.XLOOKUP(Sales[[#This Row],[Станция ДО]],Справочник_станций_и_сборов[Станция (остановка)],Справочник_станций_и_сборов[ID]),"") -> 30 | G9: Полный | H9: =IF(ISBLANK(Sales[[#This Row],[Место]]),"",IF(Sales[[#This Row],[Место]]>36, IF(MOD(Sales[[#This Row],[Место]],2)=0, "Верхнее боковое место", "Нижнее боковое место"), IF(MOD(Sales[[#This Row],[Место]],2)=0, "Верхнее место", "Нижнее место"))) -> Верхнее место | I9: =IFERROR(((_xlfn.XLOOKUP(Sales[[#This Row],[Станция ДО]],Справочник_станций_и_сборов[Станция (остановка)],Справочник_станций_и_сборов[Расстояние от Мск (км)],)-_xlfn.XLOOKUP(Sales[[#This Row],[Станция ОТ]],Справочник_станций_и_сборов[Станция (остановка)],Справочник_станций_и_сборов[Расстояние от Мск (км)],))*Справочник!$Q$3+Справочник!$Q$2),"") -> 3043.5 | J9: =IFERROR(Sales[[#This Row],[Базовая цена, руб]] * _xlfn.XLOOKUP(Sales[[#This Row],[Тип пассажира]],Тип_пассажира[Наименование],Тип_пассажира[Цена]), "") -> 0 | K9: =IFERROR(Sales[[#This Row],[Базовая цена, руб]] * VALUE(_xlfn.XLOOKUP(Sales[[#This Row],[Тип полки]], Тариф_полок[Тип полки], Тариф_полок[Коэф-нт цены], 1)),"") -> 304.35 | L9: =IFERROR((Sales[[#This Row],[Базовая цена, руб]]-Sales[[#This Row],[Сумма скидки льготникам, руб]])-Sales[[#This Row],[Сумма скидки тип-места, руб2]],"") -> 2739.15 | N9: =IF(ISBLANK(P9),"","Свободно") -> Свободно | O9: =IF(ISBLANK(P9),"",IF(P9>36, IF(MOD(P9,2)=0, "Верхнее боковое место", "Нижнее боковое место"), IF(MOD(P9,2)=0, "Верхнее место", "Нижнее место"))) -> Нижнее место | P9: 23 | Q9: =IFERROR(VLOOKUP(P9,Аналитика!A10:AH63,34,0),"") -> Целое купе/отсек | S9: Пухово | T9: =VALUE(_xlfn.XLOOKUP(S9,Справочник_станций_и_сборов[Станция (остановка)],Справочник_станций_и_сборов[ID])) -> 8
A10: =IF(ISBLANK(Sales[[#This Row],[Место]]),"",CONCATENATE("T-00"&ROW()-1)) -> T-009 | B10: 14 | C10: Миллерово | D10: Шахтная | E10: =IFERROR(_xlfn.XLOOKUP(Sales[[#This Row],[Станция ОТ]],Справочник_станций_и_сборов[Станция (остановка)],Справочник_станций_и_сборов[ID]),"") -> 16 | F10: =IFERROR(_xlfn.XLOOKUP(Sales[[#This Row],[Станция ДО]],Справочник_станций_и_сборов[Станция (остановка)],Справочник_станций_и_сборов[ID]),"") -> 24 | G10: Полный | H10: =IF(ISBLANK(Sales[[#This Row],[Место]]),"",IF(Sales[[#This Row],[Место]]>36, IF(MOD(Sales[[#This Row],[Место]],2)=0, "Верхнее боковое место", "Нижнее боковое место"), IF(MOD(Sales[[#This Row],[Место]],2)=0, "Верхнее место", "Нижнее место"))) -> Верхнее место | I10: =IFERROR(((_xlfn.XLOOKUP(Sales[[#This Row],[Станция ДО]],Справочник_станций_и_сборов[Станция (остановка)],Справочник_станций_и_сборов[Расстояние от Мск (км)],)-_xlfn.XLOOKUP(Sales[[#This Row],[Станция ОТ]],Справочник_станций_и_сборов[Станция (остановка)],Справочник_станций_и_сборов[Расстояние от Мск (км)],))*Справочник!$Q$3+Справочник!$Q$2),"") -> 1363.5 | J10: =IFERROR(Sales[[#This Row],[Базовая цена, руб]] * _xlfn.XLOOKUP(Sales[[#This Row],[Тип пассажира]],Тип_пассажира[Наименование],Тип_пассажира[Цена]), "") -> 0 | K10: =IFERROR(Sales[[#This Row],[Базовая цена, руб]] * VALUE(_xlfn.XLOOKUP(Sales[[#This Row],[Тип полки]], Тариф_полок[Тип полки], Тариф_полок[Коэф-нт цены], 1)),"") -> 136.35 | L10: =IFERROR((Sales[[#This Row],[Базовая цена, руб]]-Sales[[#This Row],[Сумма скидки льготникам, руб]])-Sales[[#This Row],[Сумма скидки тип-места, руб2]],"") -> 1227.15 | N10: =IF(ISBLANK(P10),"","Свободно") -> Свободно | O10: =IF(ISBLANK(P10),"",IF(P10>36, IF(MOD(P10,2)=0, "Верхнее боковое место", "Нижнее боковое место"), IF(MOD(P10,2)=0, "Верхнее место", "Нижнее место"))) -> Верхнее место | P10: 24 | Q10: =IFERROR(VLOOKUP(P10,Аналитика!A11:AH64,34,0),"") -> Целое купе/отсек | S10: Евдаково | T10: =VALUE(_xlfn.XLOOKUP(S10,Справочник_станций_и_сборов[Станция (остановка)],Справочник_станций_и_сборов[ID])) -> 9
A11: =IF(ISBLANK(Sales[[#This Row],[Место]]),"",CONCATENATE("T-00"&ROW()-1)) -> T-0010 | B11: 39 | C11: Мичуринск-Вор. | D11: Сулин | E11: =IFERROR(_xlfn.XLOOKUP(Sales[[#This Row],[Станция ОТ]],Справочник_станций_и_сборов[Станция (остановка)],Справочник_станций_и_сборов[ID]),"") -> 4 | F11: =IFERROR(_xlfn.XLOOKUP(Sales[[#This Row],[Станция ДО]],Справочник_станций_и_сборов[Станция (остановка)],Справочник_станций_и_сборов[ID]),"") -> 23 | G11: Полный | H11: =IF(ISBLANK(Sales[[#This Row],[Место]]),"",IF(Sales[[#This Row],[Место]]>36, IF(MOD(Sales[[#This Row],[Место]],2)=0, "Верхнее боковое место", "Нижнее боковое место"), IF(MOD(Sales[[#This Row],[Место]],2)=0, "Верхнее место", "Нижнее место"))) -> Нижнее боковое место | I11: =IFERROR(((_xlfn.XLOOKUP(Sales[[#This Row],[Станция ДО]],Справочник_станций_и_сборов[Станция (остановка)],Справочник_станций_и_сборов[Расстояние от Мск (км)],)-_xlfn.XLOOKUP(Sales[[#This Row],[Станция ОТ]],Справочник_станций_и_сборов[Станция (остановка)],Справочник_станций_и_сборов[Расстояние от Мск (км)],))*Справочник!$Q$3+Справочник!$Q$2),"") -> 3313 | J11: =IFERROR(Sales[[#This Row],[Базовая цена, руб]] * _xlfn.XLOOKUP(Sales[[#This Row],[Тип пассажира]],Тип_пассажира[Наименование],Тип_пассажира[Цена]), "") -> 0 | K11: =IFERROR(Sales[[#This Row],[Базовая цена, руб]] * VALUE(_xlfn.XLOOKUP(Sales[[#This Row],[Тип полки]], Тариф_полок[Тип полки], Тариф_полок[Коэф-нт цены], 1)),"") -> 496.95 | L11: =IFERROR((Sales[[#This Row],[Базовая цена, руб]]-Sales[[#This Row],[Сумма скидки льготникам, руб]])-Sales[[#This Row],[Сумма скидки тип-места, руб2]],"") -> 2816.05 | N11: =IF(ISBLANK(P11),"","Свободно") -> Свободно | O11: =IF(ISBLANK(P11),"",IF(P11>36, IF(MOD(P11,2)=0, "Верхнее боковое место", "Нижнее боковое место"), IF(MOD(P11,2)=0, "Верхнее место", "Нижнее место"))) -> Нижнее место | P11: 25 | Q11: =IFERROR(VLOOKUP(P11,Аналитика!A12:AH65,34,0),"") -> Целое купе/отсек | S11: Сагуны | T11: =VALUE(_xlfn.XLOOKUP(S11,Справочник_станций_и_сборов[Станция (остановка)],Справочник_станций_и_сборов[ID])) -> 10
A12: =IF(ISBLANK(Sales[[#This Row],[Место]]),"",CONCATENATE("T-00"&ROW()-1)) -> T-0011 | B12: 33 | C12: Москва (Казанский) | D12: Грязи-Воронежские | E12: =IFERROR(_xlfn.XLOOKUP(Sales[[#This Row],[Станция ОТ]],Справочник_станций_и_сборов[Станция (остановка)],Справочник_станций_и_сборов[ID]),"") -> 1 | F12: =IFERROR(_xlfn.XLOOKUP(Sales[[#This Row],[Станция ДО]],Справочник_станций_и_сборов[Станция (остановка)],Справочник_станций_и_сборов[ID]),"") -> 5 | G12: Полный | H12: =IF(ISBLANK(Sales[[#This Row],[Место]]),"",IF(Sales[[#This Row],[Место]]>36, IF(MOD(Sales[[#This Row],[Место]],2)=0, "Верхнее боковое место", "Нижнее боковое место"), IF(MOD(Sales[[#This Row],[Место]],2)=0, "Верхнее место", "Нижнее место"))) -> Нижнее место | I12: =IFERROR(((_xlfn.XLOOKUP(Sales[[#This Row],[Станция ДО]],Справочник_станций_и_сборов[Станция (остановка)],Справочник_станций_и_сборов[Расстояние от Мск (км)],)-_xlfn.XLOOKUP(Sales[[#This Row],[Станция ОТ]],Справочник_станций_и_сборов[Станция (остановка)],Справочник_станций_и_сборов[Расстояние от Мск (км)],))*Справочник!$Q$3+Справочник!$Q$2),"") -> 2448.5 | J12: =IFERROR(Sales[[#This Row],[Базовая цена, руб]] * _xlfn.XLOOKUP(Sales[[#This Row],[Тип пассажира]],Тип_пассажира[Наименование],Тип_пассажира[Цена]), "") -> 0 | K12: =IFERROR(Sales[[#This Row],[Базовая цена, руб]] * VALUE(_xlfn.XLOOKUP(Sales[[#This Row],[Тип полки]], Тариф_полок[Тип полки], Тариф_полок[Коэф-нт цены], 1)),"") -> 0 | L12: =IFERROR((Sales[[#This Row],[Базовая цена, руб]]-Sales[[#This Row],[Сумма скидки льготникам, руб]])-Sales[[#This Row],[Сумма скидки тип-места, руб2]],"") -> 2448.5 | N12: =IF(ISBLANK(P12),"","Свободно") -> Свободно | O12: =IF(ISBLANK(P12),"",IF(P12>36, IF(MOD(P12,2)=0, "Верхнее боковое место", "Нижнее боковое место"), IF(MOD(P12,2)=0, "Верхнее место", "Нижнее место"))) -> Верхнее место | P12: 26 | Q12: =IFERROR(VLOOKUP(P12,Аналитика!A13:AH66,34,0),"") -> Целое купе/отсек | S12: Подгорное | T12: =VALUE(_xlfn.XLOOKUP(S12,Справочник_станций_и_сборов[Станция (остановка)],Справочник_станций_и_сборов[ID])) -> 11
A13: =IF(ISBLANK(Sales[[#This Row],[Место]]),"",CONCATENATE("T-00"&ROW()-1)) -> T-0012 | B13: 25 | C13: Хотунок | D13: Ростов-Главный | E13: =IFERROR(_xlfn.XLOOKUP(Sales[[#This Row],[Станция ОТ]],Справочник_станций_и_сборов[Станция (остановка)],Справочник_станций_и_сборов[ID]),"") -> 27 | F13: =IFERROR(_xlfn.XLOOKUP(Sales[[#This Row],[Станция ДО]],Справочник_станций_и_сборов[Станция (остановка)],Справочник_станций_и_сборов[ID]),"") -> 30 | G13: Полный | H13: =IF(ISBLANK(Sales[[#This Row],[Место]]),"",IF(Sales[[#This Row],[Место]]>36, IF(MOD(Sales[[#This Row],[Место]],2)=0, "Верхнее боковое место", "Нижнее боковое место"), IF(MOD(Sales[[#This Row],[Место]],2)=0, "Верхнее место", "Нижнее место"))) -> Нижнее место | I13: =IFERROR(((_xlfn.XLOOKUP(Sales[[#This Row],[Станция ДО]],Справочник_станций_и_сборов[Станция (остановка)],Справочник_станций_и_сборов[Расстояние от Мск (км)],)-_xlfn.XLOOKUP(Sales[[#This Row],[Станция ОТ]],Справочник_станций_и_сборов[Станция (остановка)],Справочник_станций_и_сборов[Расстояние от Мск (км)],))*Справочник!$Q$3+Справочник!$Q$2),"") -> 940 | J13: =IFERROR(Sales[[#This Row],[Базовая цена, руб]] * _xlfn.XLOOKUP(Sales[[#This Row],[Тип пассажира]],Тип_пассажира[Наименование],Тип_пассажира[Цена]), "") -> 0 | K13: =IFERROR(Sales[[#This Row],[Базовая цена, руб]] * VALUE(_xlfn.XLOOKUP(Sales[[#This Row],[Тип полки]], Тариф_полок[Тип полки], Тариф_полок[Коэф-нт цены], 1)),"") -> 0 | L13: =IFERROR((Sales[[#This Row],[Базовая цена, руб]]-Sales[[#This Row],[Сумма скидки льготникам, руб]])-Sales[[#This Row],[Сумма скидки тип-места, руб2]],"") -> 940 | N13: =IF(ISBLANK(P13),"","Свободно") -> Свободно | O13: =IF(ISBLANK(P13),"",IF(P13>36, IF(MOD(P13,2)=0, "Верхнее боковое место", "Нижнее боковое место"), IF(MOD(P13,2)=0, "Верхнее место", "Нижнее место"))) -> Нижнее место | P13: 27 | Q13: =IFERROR(VLOOKUP(P13,Аналитика!A14:AH67,34,0),"") -> Целое купе/отсек | S13: Россошь | T13: =VALUE(_xlfn.XLOOKUP(S13,Справочник_станций_и_сборов[Станция (остановка)],Справочник_станций_и_сборов[ID])) -> 12
A14: =IF(ISBLANK(Sales[[#This Row],[Место]]),"",CONCATENATE("T-00"&ROW()-1)) -> T-0013 | B14: 5 | C14: Мичуринск-Вор. | D14: Чертково | E14: =IFERROR(_xlfn.XLOOKUP(Sales[[#This Row],[Станция ОТ]],Справочник_станций_и_сборов[Станция (остановка)],Справочник_станций_и_сборов[ID]),"") -> 4 | F14: =IFERROR(_xlfn.XLOOKUP(Sales[[#This Row],[Станция ДО]],Справочник_станций_и_сборов[Станция (остановка)],Справочник_станций_и_сборов[ID]),"") -> 15 | G14: Полный | H14: =IF(ISBLANK(Sales[[#This Row],[Место]]),"",IF(Sales[[#This Row],[Место]]>36, IF(MOD(Sales[[#This Row],[Место]],2)=0, "Верхнее боковое место", "Нижнее боковое место"), IF(MOD(Sales[[#This Row],[Место]],2)=0, "Верхнее место", "Нижнее место"))) -> Нижнее место | I14: =IFERROR(((_xlfn.XLOOKUP(Sales[[#This Row],[Станция ДО]],Справочник_станций_и_сборов[Станция (остановка)],Справочник_станций_и_сборов[Расстояние от Мск (км)],)-_xlfn.XLOOKUP(Sales[[#This Row],[Станция ОТ]],Справочник_станций_и_сборов[Станция (остановка)],Справочник_станций_и_сборов[Расстояние от Мск (км)],))*Справочник!$Q$3+Справочник!$Q$2),"") -> 2620 | J14: =IFERROR(Sales[[#This Row],[Базовая цена, руб]] * _xlfn.XLOOKUP(Sales[[#This Row],[Тип пассажира]],Тип_пассажира[Наименование],Тип_пассажира[Цена]), "") -> 0 | K14: =IFERROR(Sales[[#This Row],[Базовая цена, руб]] * VALUE(_xlfn.XLOOKUP(Sales[[#This Row],[Тип полки]], Тариф_полок[Тип полки], Тариф_полок[Коэф-нт цены], 1)),"") -> 0 | L14: =IFERROR((Sales[[#This Row],[Базовая цена, руб]]-Sales[[#This Row],[Сумма скидки льготникам, руб]])-Sales[[#This Row],[Сумма скидки тип-места, руб2]],"") -> 2620 | N14: =IF(ISBLANK(P14),"","Свободно") -> Свободно | O14: =IF(ISBLANK(P14),"",IF(P14>36, IF(MOD(P14,2)=0, "Верхнее боковое место", "Нижнее боковое место"), IF(MOD(P14,2)=0, "Верхнее место", "Нижнее место"))) -> Верхнее место | P14: 28 | Q14: =IFERROR(VLOOKUP(P14,Аналитика!A15:AH68,34,0),"") -> Целое купе/отсек | S14: Райновская | T14: =VALUE(_xlfn.XLOOKUP(S14,Справочник_станций_и_сборов[Станция (остановка)],Справочник_станций_и_сборов[ID])) -> 13
A15: =IF(ISBLANK(Sales[[#This Row],[Место]]),"",CONCATENATE("T-00"&ROW()-1)) -> T-0014 | B15: 5 | C15: Чертково | D15: Ростов-Главный | E15: =IFERROR(_xlfn.XLOOKUP(Sales[[#This Row],[Станция ОТ]],Справочник_станций_и_сборов[Станция (остановка)],Справочник_станций_и_сборов[ID]),"") -> 15 | F15: =IFERROR(_xlfn.XLOOKUP(Sales[[#This Row],[Станция ДО]],Справочник_станций_и_сборов[Станция (остановка)],Справочник_станций_и_сборов[ID]),"") -> 30 | G15: Полный | H15: =IF(ISBLANK(Sales[[#This Row],[Место]]),"",IF(Sales[[#This Row],[Место]]>36, IF(MOD(Sales[[#This Row],[Место]],2)=0, "Верхнее боковое место", "Нижнее боковое место"), IF(MOD(Sales[[#This Row],[Место]],2)=0, "Верхнее место", "Нижнее место"))) -> Нижнее место | I15: =IFERROR(((_xlfn.XLOOKUP(Sales[[#This Row],[Станция ДО]],Справочник_станций_и_сборов[Станция (остановка)],Справочник_станций_и_сборов[Расстояние от Мск (км)],)-_xlfn.XLOOKUP(Sales[[#This Row],[Станция ОТ]],Справочник_станций_и_сборов[Станция (остановка)],Справочник_станций_и_сборов[Расстояние от Мск (км)],))*Справочник!$Q$3+Справочник!$Q$2),"") -> 1850 | J15: =IFERROR(Sales[[#This Row],[Базовая цена, руб]] * _xlfn.XLOOKUP(Sales[[#This Row],[Тип пассажира]],Тип_пассажира[Наименование],Тип_пассажира[Цена]), "") -> 0 | K15: =IFERROR(Sales[[#This Row],[Базовая цена, руб]] * VALUE(_xlfn.XLOOKUP(Sales[[#This Row],[Тип полки]], Тариф_полок[Тип полки], Тариф_полок[Коэф-нт цены], 1)),"") -> 0 | L15: =IFERROR((Sales[[#This Row],[Базовая цена, руб]]-Sales[[#This Row],[Сумма скидки льготникам, руб]])-Sales[[#This Row],[Сумма скидки тип-места, руб2]],"") -> 1850 | N15: =IF(ISBLANK(P15),"","Свободно") -> Свободно | O15: =IF(ISBLANK(P15),"",IF(P15>36, IF(MOD(P15,2)=0, "Верхнее боковое место", "Нижнее боковое место"), IF(MOD(P15,2)=0, "Верхнее место", "Нижнее место"))) -> Нижнее место | P15: 29 | Q15: =IFERROR(VLOOKUP(P15,Аналитика!A16:AH69,34,0),"") -> Частично | S15: Кантемировка | T15: =VALUE(_xlfn.XLOOKUP(S15,Справочник_станций_и_сборов[Станция (остановка)],Справочник_станций_и_сборов[ID])) -> 14
A16: =IF(ISBLANK(Sales[[#This Row],[Место]]),"",CONCATENATE("T-00"&ROW()-1)) -> T-0015 | B16: 4 | C16: Каменская | D16: Ростов-Главный | E16: =IFERROR(_xlfn.XLOOKUP(Sales[[#This Row],[Станция ОТ]],Справочник_станций_и_сборов[Станция (остановка)],Справочник_станций_и_сборов[ID]),"") -> 19 | F16: =IFERROR(_xlfn.XLOOKUP(Sales[[#This Row],[Станция ДО]],Справочник_станций_и_сборов[Станция (остановка)],Справочник_станций_и_сборов[ID]),"") -> 30 | G16: Полный | H16: =IF(ISBLANK(Sales[[#This Row],[Место]]),"",IF(Sales[[#This Row],[Место]]>36, IF(MOD(Sales[[#This Row],[Место]],2)=0, "Верхнее боковое место", "Нижнее боковое место"), IF(MOD(Sales[[#This Row],[Место]],2)=0, "Верхнее место", "Нижнее место"))) -> Верхнее место | I16: =IFERROR(((_xlfn.XLOOKUP(Sales[[#This Row],[Станция ДО]],Справочник_станций_и_сборов[Станция (остановка)],Справочник_станций_и_сборов[Расстояние от Мск (км)],)-_xlfn.XLOOKUP(Sales[[#This Row],[Станция ОТ]],Справочник_станций_и_сборов[Станция (остановка)],Справочник_станций_и_сборов[Расстояние от Мск (км)],))*Справочник!$Q$3+Справочник!$Q$2),"") -> 1377.5 | J16: =IFERROR(Sales[[#This Row],[Базовая цена, руб]] * _xlfn.XLOOKUP(Sales[[#This Row],[Тип пассажира]],Тип_пассажира[Наименование],Тип_пассажира[Цена]), "") -> 0 | K16: =IFERROR(Sales[[#This Row],[Базовая цена, руб]] * VALUE(_xlfn.XLOOKUP(Sales[[#This Row],[Тип полки]], Тариф_полок[Тип полки], Тариф_полок[Коэф-нт цены], 1)),"") -> 137.75 | L16: =IFERROR((Sales[[#This Row],[Базовая цена, руб]]-Sales[[#This Row],[Сумма скидки льготникам, руб]])-Sales[[#This Row],[Сумма скидки тип-места, руб2]],"") -> 1239.75 | N16: =IF(ISBLANK(P16),"","Свободно") -> Свободно | O16: =IF(ISBLANK(P16),"",IF(P16>36, IF(MOD(P16,2)=0, "Верхнее боковое место", "Нижнее боковое место"), IF(MOD(P16,2)=0, "Верхнее место", "Нижнее место"))) -> Верхнее место | P16: 30 | Q16: =IFERROR(VLOOKUP(P16,Аналитика!A17:AH70,34,0),"") -> Частично | R16: Станция прибытия | S16: Чертково | T16: =VALUE(_xlfn.XLOOKUP(S16,Справочник_станций_и_сборов[Станция (остановка)],Справочник_станций_и_сборов[ID])) -> 15
A17: =IF(ISBLANK(Sales[[#This Row],[Место]]),"",CONCATENATE("T-00"&ROW()-1)) -> T-0016 | B17: 6 | C17: Москва (Казанский) | D17: Воронеж 1 | E17: =IFERROR(_xlfn.XLOOKUP(Sales[[#This Row],[Станция ОТ]],Справочник_станций_и_сборов[Станция (остановка)],Справочник_станций_и_сборов[ID]),"") -> 1 | F17: =IFERROR(_xlfn.XLOOKUP(Sales[[#This Row],[Станция ДО]],Справочник_станций_и_сборов[Станция (остановка)],Справочник_станций_и_сборов[ID]),"") -> 6 | G17: Полный | H17: =IF(ISBLANK(Sales[[#This Row],[Место]]),"",IF(Sales[[#This Row],[Место]]>36, IF(MOD(Sales[[#This Row],[Место]],2)=0, "Верхнее боковое место", "Нижнее боковое место"), IF(MOD(Sales[[#This Row],[Место]],2)=0, "Верхнее место", "Нижнее место"))) -> Верхнее место | I17: =IFERROR(((_xlfn.XLOOKUP(Sales[[#This Row],[Станция ДО]],Справочник_станций_и_сборов[Станция (остановка)],Справочник_станций_и_сборов[Расстояние от Мск (км)],)-_xlfn.XLOOKUP(Sales[[#This Row],[Станция ОТ]],Справочник_станций_и_сборов[Станция (остановка)],Справочник_станций_и_сборов[Расстояние от Мск (км)],))*Справочник!$Q$3+Справочник!$Q$2),"") -> 2861.5 | J17: =IFERROR(Sales[[#This Row],[Базовая цена, руб]] * _xlfn.XLOOKUP(Sales[[#This Row],[Тип пассажира]],Тип_пассажира[Наименование],Тип_пассажира[Цена]), "") -> 0 | K17: =IFERROR(Sales[[#This Row],[Базовая цена, руб]] * VALUE(_xlfn.XLOOKUP(Sales[[#This Row],[Тип полки]], Тариф_полок[Тип полки], Тариф_полок[Коэф-нт цены], 1)),"") -> 286.15 | L17: =IFERROR((Sales[[#This Row],[Базовая цена, руб]]-Sales[[#This Row],[Сумма скидки льготникам, руб]])-Sales[[#This Row],[Сумма скидки тип-места, руб2]],"") -> 2575.35 | N17: =IF(ISBLANK(P17),"","Свободно") -> Свободно | O17: =IF(ISBLANK(P17),"",IF(P17>36, IF(MOD(P17,2)=0, "Верхнее боковое место", "Нижнее боковое место"), IF(MOD(P17,2)=0, "Верхнее место", "Нижнее место"))) -> Нижнее место | P17: 31 | Q17: =IFERROR(VLOOKUP(P17,Аналитика!A18:AH71,34,0),"") -> Частично | S17: Миллерово | T17: =VALUE(_xlfn.XLOOKUP(S17,Справочник_станций_и_сборов[Станция (остановка)],Справочник_станций_и_сборов[ID])) -> 16
A18: =IF(ISBLANK(Sales[[#This Row],[Место]]),"",CONCATENATE("T-00"&ROW()-1)) -> T-0017 | B18: 7 | C18: Москва (Казанский) | D18: Миллерово | E18: =IFERROR(_xlfn.XLOOKUP(Sales[[#This Row],[Станция ОТ]],Справочник_станций_и_сборов[Станция (остановка)],Справочник_станций_и_сборов[ID]),"") -> 1 | F18: =IFERROR(_xlfn.XLOOKUP(Sales[[#This Row],[Станция ДО]],Справочник_станций_и_сборов[Станция (остановка)],Справочник_станций_и_сборов[ID]),"") -> 16 | G18: Полный | H18: =IF(ISBLANK(Sales[[#This Row],[Место]]),"",IF(Sales[[#This Row],[Место]]>36, IF(MOD(Sales[[#This Row],[Место]],2)=0, "Верхнее боковое место", "Нижнее боковое место"), IF(MOD(Sales[[#This Row],[Место]],2)=0, "Верхнее место", "Нижнее место"))) -> Нижнее место | I18: =IFERROR(((_xlfn.XLOOKUP(Sales[[#This Row],[Станция ДО]],Справочник_станций_и_сборов[Станция (остановка)],Справочник_станций_и_сборов[Расстояние от Мск (км)],)-_xlfn.XLOOKUP(Sales[[#This Row],[Станция ОТ]],Справочник_станций_и_сборов[Станция (остановка)],Справочник_станций_и_сборов[Расстояние от Мск (км)],))*Справочник!$Q$3+Справочник!$Q$2),"") -> 4286 | J18: =IFERROR(Sales[[#This Row],[Базовая цена, руб]] * _xlfn.XLOOKUP(Sales[[#This Row],[Тип пассажира]],Тип_пассажира[Наименование],Тип_пассажира[Цена]), "") -> 0 | K18: =IFERROR(Sales[[#This Row],[Базовая цена, руб]] * VALUE(_xlfn.XLOOKUP(Sales[[#This Row],[Тип полки]], Тариф_полок[Тип полки], Тариф_полок[Коэф-нт цены], 1)),"") -> 0 | L18: =IFERROR((Sales[[#This Row],[Базовая цена, руб]]-Sales[[#This Row],[Сумма скидки льготникам, руб]])-Sales[[#This Row],[Сумма скидки тип-места, руб2]],"") -> 4286 | N18: =IF(ISBLANK(P18),"","Свободно") -> Свободно | O18: =IF(ISBLANK(P18),"",IF(P18>36, IF(MOD(P18,2)=0, "Верхнее боковое место", "Нижнее боковое место"), IF(MOD(P18,2)=0, "Верхнее место", "Нижнее место"))) -> Верхнее место | P18: 32 | Q18: =IFERROR(VLOOKUP(P18,Аналитика!A19:AH72,34,0),"") -> Частично | S18: Тарасовка | T18: =VALUE(_xlfn.XLOOKUP(S18,Справочник_станций_и_сборов[Станция (остановка)],Справочник_станций_и_сборов[ID])) -> 17
A19: =IF(ISBLANK(Sales[[#This Row],[Место]]),"",CONCATENATE("T-00"&ROW()-1)) -> T-0018 | B19: 8 | C19: Москва (Казанский) | D19: Лиски | E19: =IFERROR(_xlfn.XLOOKUP(Sales[[#This Row],[Станция ОТ]],Справочник_станций_и_сборов[Станция (остановка)],Справочник_станций_и_сборов[ID]),"") -> 1 | F19: =IFERROR(_xlfn.XLOOKUP(Sales[[#This Row],[Станция ДО]],Справочник_станций_и_сборов[Станция (остановка)],Справочник_станций_и_сборов[ID]),"") -> 7 | G19: Полный | H19: =IF(ISBLANK(Sales[[#This Row],[Место]]),"",IF(Sales[[#This Row],[Место]]>36, IF(MOD(Sales[[#This Row],[Место]],2)=0, "Верхнее боковое место", "Нижнее боковое место"), IF(MOD(Sales[[#This Row],[Место]],2)=0, "Верхнее место", "Нижнее место"))) -> Верхнее место | I19: =IFERROR(((_xlfn.XLOOKUP(Sales[[#This Row],[Станция ДО]],Справочник_станций_и_сборов[Станция (остановка)],Справочник_станций_и_сборов[Расстояние от Мск (км)],)-_xlfn.XLOOKUP(Sales[[#This Row],[Станция ОТ]],Справочник_станций_и_сборов[Станция (остановка)],Справочник_станций_и_сборов[Расстояние от Мск (км)],))*Справочник!$Q$3+Справочник!$Q$2),"") -> 3204.5 | J19: =IFERROR(Sales[[#This Row],[Базовая цена, руб]] * _xlfn.XLOOKUP(Sales[[#This Row],[Тип пассажира]],Тип_пассажира[Наименование],Тип_пассажира[Цена]), "") -> 0 | K19: =IFERROR(Sales[[#This Row],[Базовая цена, руб]] * VALUE(_xlfn.XLOOKUP(Sales[[#This Row],[Тип полки]], Тариф_полок[Тип полки], Тариф_полок[Коэф-нт цены], 1)),"") -> 320.45 | L19: =IFERROR((Sales[[#This Row],[Базовая цена, руб]]-Sales[[#This Row],[Сумма скидки льготникам, руб]])-Sales[[#This Row],[Сумма скидки тип-места, руб2]],"") -> 2884.05 | N19: =IF(ISBLANK(P19),"","Свободно") -> Свободно | O19: =IF(ISBLANK(P19),"",IF(P19>36, IF(MOD(P19,2)=0, "Верхнее боковое место", "Нижнее боковое место"), IF(MOD(P19,2)=0, "Верхнее место", "Нижнее место"))) -> Верхнее место | P19: 34 | Q19: =IFERROR(VLOOKUP(P19,Аналитика!A20:AH73,34,0),"") -> Частично | S19: Глубокая | T19: =VALUE(_xlfn.XLOOKUP(S19,Справочник_станций_и_сборов[Станция (остановка)],Справочник_станций_и_сборов[ID])) -> 18
A20: =IF(ISBLANK(Sales[[#This Row],[Место]]),"",CONCATENATE("T-00"&ROW()-1)) -> T-0019 | B20: 9 | C20: Москва (Казанский) | D20: Воронеж 1 | E20: =IFERROR(_xlfn.XLOOKUP(Sales[[#This Row],[Станция ОТ]],Справочник_станций_и_сборов[Станция (остановка)],Справочник_станций_и_сборов[ID]),"") -> 1 | F20: =IFERROR(_xlfn.XLOOKUP(Sales[[#This Row],[Станция ДО]],Справочник_станций_и_сборов[Станция (остановка)],Справочник_станций_и_сборов[ID]),"") -> 6 | G20: Полный | H20: =IF(ISBLANK(Sales[[#This Row],[Место]]),"",IF(Sales[[#This Row],[Место]]>36, IF(MOD(Sales[[#This Row],[Место]],2)=0, "Верхнее боковое место", "Нижнее боковое место"), IF(MOD(Sales[[#This Row],[Место]],2)=0, "Верхнее место", "Нижнее место"))) -> Нижнее место | I20: =IFERROR(((_xlfn.XLOOKUP(Sales[[#This Row],[Станция ДО]],Справочник_станций_и_сборов[Станция (остановка)],Справочник_станций_и_сборов[Расстояние от Мск (км)],)-_xlfn.XLOOKUP(Sales[[#This Row],[Станция ОТ]],Справочник_станций_и_сборов[Станция (остановка)],Справочник_станций_и_сборов[Расстояние от Мск (км)],))*Справочник!$Q$3+Справочник!$Q$2),"") -> 2861.5 | J20: =IFERROR(Sales[[#This Row],[Базовая цена, руб]] * _xlfn.XLOOKUP(Sales[[#This Row],[Тип пассажира]],Тип_пассажира[Наименование],Тип_пассажира[Цена]), "") -> 0 | K20: =IFERROR(Sales[[#This Row],[Базовая цена, руб]] * VALUE(_xlfn.XLOOKUP(Sales[[#This Row],[Тип полки]], Тариф_полок[Тип полки], Тариф_полок[Коэф-нт цены], 1)),"") -> 0 | L20: =IFERROR((Sales[[#This Row],[Базовая цена, руб]]-Sales[[#This Row],[Сумма скидки льготникам, руб]])-Sales[[#This Row],[Сумма скидки тип-места, руб2]],"") -> 2861.5 | N20: =IF(ISBLANK(P20),"","Свободно") -> Свободно | O20: =IF(ISBLANK(P20),"",IF(P20>36, IF(MOD(P20,2)=0, "Верхнее боковое место", "Нижнее боковое место"), IF(MOD(P20,2)=0, "Верхнее место", "Нижнее место"))) -> Нижнее место | P20: 35 | Q20: =IFERROR(VLOOKUP(P20,Аналитика!A21:AH74,34,0),"") -> Частично | S20: Каменская | T20: =VALUE(_xlfn.XLOOKUP(S20,Справочник_станций_и_сборов[Станция (остановка)],Справочник_станций_и_сборов[ID])) -> 19
A21: =IF(ISBLANK(Sales[[#This Row],[Место]]),"",CONCATENATE("T-00"&ROW()-1)) -> T-0020 | B21: 10 | C21: Москва (Казанский) | D21: Ростов-Главный | E21: =IFERROR(_xlfn.XLOOKUP(Sales[[#This Row],[Станция ОТ]],Справочник_станций_и_сборов[Станция (остановка)],Справочник_станций_и_сборов[ID]),"") -> 1 | F21: =IFERROR(_xlfn.XLOOKUP(Sales[[#This Row],[Станция ДО]],Справочник_станций_и_сборов[Станция (остановка)],Справочник_станций_и_сборов[ID]),"") -> 30 | G21: Полный | H21: =IF(ISBLANK(Sales[[#This Row],[Место]]),"",IF(Sales[[#This Row],[Место]]>36, IF(MOD(Sales[[#This Row],[Место]],2)=0, "Верхнее боковое место", "Нижнее боковое место"), IF(MOD(Sales[[#This Row],[Место]],2)=0, "Верхнее место", "Нижнее место"))) -> Верхнее место | I21: =IFERROR(((_xlfn.XLOOKUP(Sales[[#This Row],[Станция ДО]],Справочник_станций_и_сборов[Станция (остановка)],Справочник_станций_и_сборов[Расстояние от Мск (км)],)-_xlfn.XLOOKUP(Sales[[#This Row],[Станция ОТ]],Справочник_станций_и_сборов[Станция (остановка)],Справочник_станций_и_сборов[Расстояние от Мск (км)],))*Справочник!$Q$3+Справочник!$Q$2),"") -> 5105 | J21: =IFERROR(Sales[[#This Row],[Базовая цена, руб]] * _xlfn.XLOOKUP(Sales[[#This Row],[Тип пассажира]],Тип_пассажира[Наименование],Тип_пассажира[Цена]), "") -> 0 | K21: =IFERROR(Sales[[#This Row],[Базовая цена, руб]] * VALUE(_xlfn.XLOOKUP(Sales[[#This Row],[Тип полки]], Тариф_полок[Тип полки], Тариф_полок[Коэф-нт цены], 1)),"") -> 510.5 | L21: =IFERROR((Sales[[#This Row],[Базовая цена, руб]]-Sales[[#This Row],[Сумма скидки льготникам, руб]])-Sales[[#This Row],[Сумма скидки тип-места, руб2]],"") -> 4594.5 | N21: =IF(ISBLANK(P21),"","Свободно") -> Свободно | O21: =IF(ISBLANK(P21),"",IF(P21>36, IF(MOD(P21,2)=0, "Верхнее боковое место", "Нижнее боковое место"), IF(MOD(P21,2)=0, "Верхнее место", "Нижнее место"))) -> Верхнее место | P21: 36 | Q21: =IFERROR(VLOOKUP(P21,Аналитика!A22:AH75,34,0),"") -> Частично | S21: Лихая | T21: =VALUE(_xlfn.XLOOKUP(S21,Справочник_станций_и_сборов[Станция (остановка)],Справочник_станций_и_сборов[ID])) -> 20
A22: =IF(ISBLANK(Sales[[#This Row],[Место]]),"",CONCATENATE("T-00"&ROW()-1)) -> T-0021 | B22: 6 | C22: Воронеж 1 | D22: Глубокая | E22: =IFERROR(_xlfn.XLOOKUP(Sales[[#This Row],[Станция ОТ]],Справочник_станций_и_сборов[Станция (остановка)],Справочник_станций_и_сборов[ID]),"") -> 6 | F22: =IFERROR(_xlfn.XLOOKUP(Sales[[#This Row],[Станция ДО]],Справочник_станций_и_сборов[Станция (остановка)],Справочник_станций_и_сборов[ID]),"") -> 18 | G22: Полный | H22: =IF(ISBLANK(Sales[[#This Row],[Место]]),"",IF(Sales[[#This Row],[Место]]>36, IF(MOD(Sales[[#This Row],[Место]],2)=0, "Верхнее боковое место", "Нижнее боковое место"), IF(MOD(Sales[[#This Row],[Место]],2)=0, "Верхнее место", "Нижнее место"))) -> Верхнее место | I22: =IFERROR(((_xlfn.XLOOKUP(Sales[[#This Row],[Станция ДО]],Справочник_станций_и_сборов[Станция (остановка)],Справочник_станций_и_сборов[Расстояние от Мск (км)],)-_xlfn.XLOOKUP(Sales[[#This Row],[Станция ОТ]],Справочник_станций_и_сборов[Станция (остановка)],Справочник_станций_и_сборов[Расстояние от Мск (км)],))*Справочник!$Q$3+Справочник!$Q$2),"") -> 2385.5 | J22: =IFERROR(Sales[[#This Row],[Базовая цена, руб]] * _xlfn.XLOOKUP(Sales[[#This Row],[Тип пассажира]],Тип_пассажира[Наименование],Тип_пассажира[Цена]), "") -> 0 | K22: =IFERROR(Sales[[#This Row],[Базовая цена, руб]] * VALUE(_xlfn.XLOOKUP(Sales[[#This Row],[Тип полки]], Тариф_полок[Тип полки], Тариф_полок[Коэф-нт цены], 1)),"") -> 238.55 | L22: =IFERROR((Sales[[#This Row],[Базовая цена, руб]]-Sales[[#This Row],[Сумма скидки льготникам, руб]])-Sales[[#This Row],[Сумма скидки тип-места, руб2]],"") -> 2146.95 | N22: =IF(ISBLANK(P22),"","Свободно") -> Свободно | O22: =IF(ISBLANK(P22),"",IF(P22>36, IF(MOD(P22,2)=0, "Верхнее боковое место", "Нижнее боковое место"), IF(MOD(P22,2)=0, "Верхнее место", "Нижнее место"))) -> Нижнее боковое место | P22: 37 | Q22: =IFERROR(VLOOKUP(P22,Аналитика!A23:AH76,34,0),"") -> Частично | S22: Замчалово | T22: =VALUE(_xlfn.XLOOKUP(S22,Справочник_станций_и_сборов[Станция (остановка)],Справочник_станций_и_сборов[ID])) -> 21
A23: =IF(ISBLANK(Sales[[#This Row],[Место]]),"",CONCATENATE("T-00"&ROW()-1)) -> T-0022 | B23: 11 | C23: Москва (Казанский) | D23: Ростов-Главный | E23: =IFERROR(_xlfn.XLOOKUP(Sales[[#This Row],[Станция ОТ]],Справочник_станций_и_сборов[Станция (остановка)],Справочник_станций_и_сборов[ID]),"") -> 1 | F23: =IFERROR(_xlfn.XLOOKUP(Sales[[#This Row],[Станция ДО]],Справочник_станций_и_сборов[Станция (остановка)],Справочник_станций_и_сборов[ID]),"") -> 30 | G23: Дети (до 10 лет): | H23: =IF(ISBLANK(Sales[[#This Row],[Место]]),"",IF(Sales[[#This Row],[Место]]>36, IF(MOD(Sales[[#This Row],[Место]],2)=0, "Верхнее боковое место", "Нижнее боковое место"), IF(MOD(Sales[[#This Row],[Место]],2)=0, "Верхнее место", "Нижнее место"))) -> Нижнее место | I23: =IFERROR(((_xlfn.XLOOKUP(Sales[[#This Row],[Станция ДО]],Справочник_станций_и_сборов[Станция (остановка)],Справочник_станций_и_сборов[Расстояние от Мск (км)],)-_xlfn.XLOOKUP(Sales[[#This Row],[Станция ОТ]],Справочник_станций_и_сборов[Станция (остановка)],Справочник_станций_и_сборов[Расстояние от Мск (км)],))*Справочник!$Q$3+Справочник!$Q$2),"") -> 5105 | J23: =IFERROR(Sales[[#This Row],[Базовая цена, руб]] * _xlfn.XLOOKUP(Sales[[#This Row],[Тип пассажира]],Тип_пассажира[Наименование],Тип_пассажира[Цена]), "") -> 1786.75 | K23: =IFERROR(Sales[[#This Row],[Базовая цена, руб]] * VALUE(_xlfn.XLOOKUP(Sales[[#This Row],[Тип полки]], Тариф_полок[Тип полки], Тариф_полок[Коэф-нт цены], 1)),"") -> 0 | L23: =IFERROR((Sales[[#This Row],[Базовая цена, руб]]-Sales[[#This Row],[Сумма скидки льготникам, руб]])-Sales[[#This Row],[Сумма скидки тип-места, руб2]],"") -> 3318.25 | N23: =IF(ISBLANK(P23),"","Свободно") -> Свободно | O23: =IF(ISBLANK(P23),"",IF(P23>36, IF(MOD(P23,2)=0, "Верхнее боковое место", "Нижнее боковое место"), IF(MOD(P23,2)=0, "Верхнее место", "Нижнее место"))) -> Верхнее боковое место | P23: 38 | Q23: =IFERROR(VLOOKUP(P23,Аналитика!A24:AH77,34,0),"") -> Частично | S23: Зверево | T23: =VALUE(_xlfn.XLOOKUP(S23,Справочник_станций_и_сборов[Станция (остановка)],Справочник_станций_и_сборов[ID])) -> 22
A24: =IF(ISBLANK(Sales[[#This Row],[Место]]),"",CONCATENATE("T-00"&ROW()-1)) -> T-0023 | B24: 12 | C24: Москва (Казанский) | D24: Ростов-Главный | E24: =IFERROR(_xlfn.XLOOKUP(Sales[[#This Row],[Станция ОТ]],Справочник_станций_и_сборов[Станция (остановка)],Справочник_станций_и_сборов[ID]),"") -> 1 | F24: =IFERROR(_xlfn.XLOOKUP(Sales[[#This Row],[Станция ДО]],Справочник_станций_и_сборов[Станция (остановка)],Справочник_станций_и_сборов[ID]),"") -> 30 | G24: Школьники/Студенты: | H24: =IF(ISBLANK(Sales[[#This Row],[Место]]),"",IF(Sales[[#This Row],[Место]]>36, IF(MOD(Sales[[#This Row],[Место]],2)=0, "Верхнее боковое место", "Нижнее боковое место"), IF(MOD(Sales[[#This Row],[Место]],2)=0, "Верхнее место", "Нижнее место"))) -> Верхнее место | I24: =IFERROR(((_xlfn.XLOOKUP(Sales[[#This Row],[Станция ДО]],Справочник_станций_и_сборов[Станция (остановка)],Справочник_станций_и_сборов[Расстояние от Мск (км)],)-_xlfn.XLOOKUP(Sales[[#This Row],[Станция ОТ]],Справочник_станций_и_сборов[Станция (остановка)],Справочник_станций_и_сборов[Расстояние от Мск (км)],))*Справочник!$Q$3+Справочник!$Q$2),"") -> 5105 | J24: =IFERROR(Sales[[#This Row],[Базовая цена, руб]] * _xlfn.XLOOKUP(Sales[[#This Row],[Тип пассажира]],Тип_пассажира[Наименование],Тип_пассажира[Цена]), "") -> 2552.5 | K24: =IFERROR(Sales[[#This Row],[Базовая цена, руб]] * VALUE(_xlfn.XLOOKUP(Sales[[#This Row],[Тип полки]], Тариф_полок[Тип полки], Тариф_полок[Коэф-нт цены], 1)),"") -> 510.5 | L24: =IFERROR((Sales[[#This Row],[Базовая цена, руб]]-Sales[[#This Row],[Сумма скидки льготникам, руб]])-Sales[[#This Row],[Сумма скидки тип-места, руб2]],"") -> 2042 | N24: =IF(ISBLANK(P24),"","Свободно") -> Свободно | O24: =IF(ISBLANK(P24),"",IF(P24>36, IF(MOD(P24,2)=0, "Верхнее боковое место", "Нижнее боковое место"), IF(MOD(P24,2)=0, "Верхнее место", "Нижнее место"))) -> Верхнее боковое место | P24: 40 | Q24: =IFERROR(VLOOKUP(P24,Аналитика!A25:AH78,34,0),"") -> Частично | S24: Сулин | T24: =VALUE(_xlfn.XLOOKUP(S24,Справочник_станций_и_сборов[Станция (остановка)],Справочник_станций_и_сборов[ID])) -> 23
A25: =IF(ISBLANK(Sales[[#This Row],[Место]]),"",CONCATENATE("T-00"&ROW()-1)) -> T-0024 | B25: 0 | C25: Москва (Казанский) | D25: Ростов-Главный | E25: =IFERROR(_xlfn.XLOOKUP(Sales[[#This Row],[Станция ОТ]],Справочник_станций_и_сборов[Станция (остановка)],Справочник_станций_и_сборов[ID]),"") -> 1 | F25: =IFERROR(_xlfn.XLOOKUP(Sales[[#This Row],[Станция ДО]],Справочник_станций_и_сборов[Станция (остановка)],Справочник_станций_и_сборов[ID]),"") -> 30 | G25: Младенцы (до 5 лет): | H25: =IF(ISBLANK(Sales[[#This Row],[Место]]),"",IF(Sales[[#This Row],[Место]]>36, IF(MOD(Sales[[#This Row],[Место]],2)=0, "Верхнее боковое место", "Нижнее боковое место"), IF(MOD(Sales[[#This Row],[Место]],2)=0, "Верхнее место", "Нижнее место"))) -> Верхнее место | I25: =IFERROR(((_xlfn.XLOOKUP(Sales[[#This Row],[Станция ДО]],Справочник_станций_и_сборов[Станция (остановка)],Справочник_станций_и_сборов[Расстояние от Мск (км)],)-_xlfn.XLOOKUP(Sales[[#This Row],[Станция ОТ]],Справочник_станций_и_сборов[Станция (остановка)],Справочник_станций_и_сборов[Расстояние от Мск (км)],))*Справочник!$Q$3+Справочник!$Q$2),"") -> 5105 | J25: =IFERROR(Sales[[#This Row],[Базовая цена, руб]] * _xlfn.XLOOKUP(Sales[[#This Row],[Тип пассажира]],Тип_пассажира[Наименование],Тип_пассажира[Цена]), "") -> 5105 | K25: =IFERROR(Sales[[#This Row],[Базовая цена, руб]] * VALUE(_xlfn.XLOOKUP(Sales[[#This Row],[Тип полки]], Тариф_полок[Тип полки], Тариф_полок[Коэф-нт цены], 1)),"") -> 510.5 | L25: =IFERROR((Sales[[#This Row],[Базовая цена, руб]]-Sales[[#This Row],[Сумма скидки льготникам, руб]])-Sales[[#This Row],[Сумма скидки тип-места, руб2]],"") -> -510.5 | N25: =IF(ISBLANK(P25),"","Свободно") -> Свободно | O25: =IF(ISBLANK(P25),"",IF(P25>36, IF(MOD(P25,2)=0, "Верхнее боковое место", "Нижнее боковое место"), IF(MOD(P25,2)=0, "Верхнее место", "Нижнее место"))) -> Нижнее боковое место | P25: 41 | Q25: =IFERROR(VLOOKUP(P25,Аналитика!A26:AH79,34,0),"") -> Целое купе/отсек | S25: Шахтная | T25: =VALUE(_xlfn.XLOOKUP(S25,Справочник_станций_и_сборов[Станция (остановка)],Справочник_станций_и_сборов[ID])) -> 24
A26: =IF(ISBLANK(Sales[[#This Row],[Место]]),"",CONCATENATE("T-00"&ROW()-1)) -> T-0025 | B26: 3 | C26: Лиски | D26: Россошь | E26: =IFERROR(_xlfn.XLOOKUP(Sales[[#This Row],[Станция ОТ]],Справочник_станций_и_сборов[Станция (остановка)],Справочник_станций_и_сборов[ID]),"") -> 7 | F26: =IFERROR(_xlfn.XLOOKUP(Sales[[#This Row],[Станция ДО]],Справочник_станций_и_сборов[Станция (остановка)],Справочник_станций_и_сборов[ID]),"") -> 12 | G26: Полный | H26: =IF(ISBLANK(Sales[[#This Row],[Место]]),"",IF(Sales[[#This Row],[Место]]>36, IF(MOD(Sales[[#This Row],[Место]],2)=0, "Верхнее боковое место", "Нижнее боковое место"), IF(MOD(Sales[[#This Row],[Место]],2)=0, "Верхнее место", "Нижнее место"))) -> Нижнее место | I26: =IFERROR(((_xlfn.XLOOKUP(Sales[[#This Row],[Станция ДО]],Справочник_станций_и_сборов[Станция (остановка)],Справочник_станций_и_сборов[Расстояние от Мск (км)],)-_xlfn.XLOOKUP(Sales[[#This Row],[Станция ОТ]],Справочник_станций_и_сборов[Станция (остановка)],Справочник_станций_и_сборов[Расстояние от Мск (км)],))*Справочник!$Q$3+Справочник!$Q$2),"") -> 1276 | J26: =IFERROR(Sales[[#This Row],[Базовая цена, руб]] * _xlfn.XLOOKUP(Sales[[#This Row],[Тип пассажира]],Тип_пассажира[Наименование],Тип_пассажира[Цена]), "") -> 0 | K26: =IFERROR(Sales[[#This Row],[Базовая цена, руб]] * VALUE(_xlfn.XLOOKUP(Sales[[#This Row],[Тип полки]], Тариф_полок[Тип полки], Тариф_полок[Коэф-нт цены], 1)),"") -> 0 | L26: =IFERROR((Sales[[#This Row],[Базовая цена, руб]]-Sales[[#This Row],[Сумма скидки льготникам, руб]])-Sales[[#This Row],[Сумма скидки тип-места, руб2]],"") -> 1276 | N26: =IF(ISBLANK(P26),"","Свободно") -> Свободно | O26: =IF(ISBLANK(P26),"",IF(P26>36, IF(MOD(P26,2)=0, "Верхнее боковое место", "Нижнее боковое место"), IF(MOD(P26,2)=0, "Верхнее место", "Нижнее место"))) -> Верхнее боковое место | P26: 42 | Q26: =IFERROR(VLOOKUP(P26,Аналитика!A27:AH80,34,0),"") -> Целое купе/отсек | S26: Каменоломни | T26: =VALUE(_xlfn.XLOOKUP(S26,Справочник_станций_и_сборов[Станция (остановка)],Справочник_станций_и_сборов[ID])) -> 25
A27: =IF(ISBLANK(Sales[[#This Row],[Место]]),"",CONCATENATE("T-00"&ROW()-1)) -> T-0026 | B27: 13 | C27: Грязи-Воронежские | D27: Новочеркасск | E27: =IFERROR(_xlfn.XLOOKUP(Sales[[#This Row],[Станция ОТ]],Справочник_станций_и_сборов[Станция (остановка)],Справочник_станций_и_сборов[ID]),"") -> 5 | F27: =IFERROR(_xlfn.XLOOKUP(Sales[[#This Row],[Станция ДО]],Справочник_станций_и_сборов[Станция (остановка)],Справочник_станций_и_сборов[ID]),"") -> 28 | G27: Полный | H27: =IF(ISBLANK(Sales[[#This Row],[Место]]),"",IF(Sales[[#This Row],[Место]]>36, IF(MOD(Sales[[#This Row],[Место]],2)=0, "Верхнее боковое место", "Нижнее боковое место"), IF(MOD(Sales[[#This Row],[Место]],2)=0, "Верхнее место", "Нижнее место"))) -> Нижнее место | I27: =IFERROR(((_xlfn.XLOOKUP(Sales[[#This Row],[Станция ДО]],Справочник_станций_и_сборов[Станция (остановка)],Справочник_станций_и_сборов[Расстояние от Мск (км)],)-_xlfn.XLOOKUP(Sales[[#This Row],[Станция ОТ]],Справочник_станций_и_сборов[Станция (остановка)],Справочник_станций_и_сборов[Расстояние от Мск (км)],))*Справочник!$Q$3+Справочник!$Q$2),"") -> 3334 | J27: =IFERROR(Sales[[#This Row],[Базовая цена, руб]] * _xlfn.XLOOKUP(Sales[[#This Row],[Тип пассажира]],Тип_пассажира[Наименование],Тип_пассажира[Цена]), "") -> 0 | K27: =IFERROR(Sales[[#This Row],[Базовая цена, руб]] * VALUE(_xlfn.XLOOKUP(Sales[[#This Row],[Тип полки]], Тариф_полок[Тип полки], Тариф_полок[Коэф-нт цены], 1)),"") -> 0 | L27: =IFERROR((Sales[[#This Row],[Базовая цена, руб]]-Sales[[#This Row],[Сумма скидки льготникам, руб]])-Sales[[#This Row],[Сумма скидки тип-места, руб2]],"") -> 3334 | N27: =IF(ISBLANK(P27),"","Свободно") -> Свободно | O27: =IF(ISBLANK(P27),"",IF(P27>36, IF(MOD(P27,2)=0, "Верхнее боковое место", "Нижнее боковое место"), IF(MOD(P27,2)=0, "Верхнее место", "Нижнее место"))) -> Нижнее боковое место | P27: 43 | Q27: =IFERROR(VLOOKUP(P27,Аналитика!A28:AH81,34,0),"") -> Целое купе/отсек | S27: Персиановка | T27: =VALUE(_xlfn.XLOOKUP(S27,Справочник_станций_и_сборов[Станция (остановка)],Справочник_станций_и_сборов[ID])) -> 26
A28: =IF(ISBLANK(Sales[[#This Row],[Место]]),"",CONCATENATE("T-00"&ROW()-1)) -> T-0027 | B28: 14 | C28: Москва (Казанский) | D28: Чертково | E28: =IFERROR(_xlfn.XLOOKUP(Sales[[#This Row],[Станция ОТ]],Справочник_станций_и_сборов[Станция (остановка)],Справочник_станций_и_сборов[ID]),"") -> 1 | F28: =IFERROR(_xlfn.XLOOKUP(Sales[[#This Row],[Станция ДО]],Справочник_станций_и_сборов[Станция (остановка)],Справочник_станций_и_сборов[ID]),"") -> 15 | G28: Полный | H28: =IF(ISBLANK(Sales[[#This Row],[Место]]),"",IF(Sales[[#This Row],[Место]]>36, IF(MOD(Sales[[#This Row],[Место]],2)=0, "Верхнее боковое место", "Нижнее боковое место"), IF(MOD(Sales[[#This Row],[Место]],2)=0, "Верхнее место", "Нижнее место"))) -> Верхнее место | I28: =IFERROR(((_xlfn.XLOOKUP(Sales[[#This Row],[Станция ДО]],Справочник_станций_и_сборов[Станция (остановка)],Справочник_станций_и_сборов[Расстояние от Мск (км)],)-_xlfn.XLOOKUP(Sales[[#This Row],[Станция ОТ]],Справочник_станций_и_сборов[Станция (остановка)],Справочник_станций_и_сборов[Расстояние от Мск (км)],))*Справочник!$Q$3+Справочник!$Q$2),"") -> 4055 | J28: =IFERROR(Sales[[#This Row],[Базовая цена, руб]] * _xlfn.XLOOKUP(Sales[[#This Row],[Тип пассажира]],Тип_пассажира[Наименование],Тип_пассажира[Цена]), "") -> 0 | K28: =IFERROR(Sales[[#This Row],[Базовая цена, руб]] * VALUE(_xlfn.XLOOKUP(Sales[[#This Row],[Тип полки]], Тариф_полок[Тип полки], Тариф_полок[Коэф-нт цены], 1)),"") -> 405.5 | L28: =IFERROR((Sales[[#This Row],[Базовая цена, руб]]-Sales[[#This Row],[Сумма скидки льготникам, руб]])-Sales[[#This Row],[Сумма скидки тип-места, руб2]],"") -> 3649.5 | N28: =IF(ISBLANK(P28),"","Свободно") -> Свободно | O28: =IF(ISBLANK(P28),"",IF(P28>36, IF(MOD(P28,2)=0, "Верхнее боковое место", "Нижнее боковое место"), IF(MOD(P28,2)=0, "Верхнее место", "Нижнее место"))) -> Верхнее боковое место | P28: 44 | Q28: =IFERROR(VLOOKUP(P28,Аналитика!A29:AH82,34,0),"") -> Целое купе/отсек | S28: Хотунок | T28: =VALUE(_xlfn.XLOOKUP(S28,Справочник_станций_и_сборов[Станция (остановка)],Справочник_станций_и_сборов[ID])) -> 27
A29: =IF(ISBLANK(Sales[[#This Row],[Место]]),"",CONCATENATE("T-00"&ROW()-1)) | E29: =IFERROR(_xlfn.XLOOKUP(Sales[[#This Row],[Станция ОТ]],Справочник_станций_и_сборов[Станция (остановка)],Справочник_станций_и_сборов[ID]),"") | F29: =IFERROR(_xlfn.XLOOKUP(Sales[[#This Row],[Станция ДО]],Справочник_станций_и_сборов[Станция (остановка)],Справочник_станций_и_сборов[ID]),"") | H29: =IF(ISBLANK(Sales[[#This Row],[Место]]),"",IF(Sales[[#This Row],[Место]]>36, IF(MOD(Sales[[#This Row],[Место]],2)=0, "Верхнее боковое место", "Нижнее боковое место"), IF(MOD(Sales[[#This Row],[Место]],2)=0, "Верхнее место", "Нижнее место"))) | I29: =IFERROR(((_xlfn.XLOOKUP(Sales[[#This Row],[Станция ДО]],Справочник_станций_и_сборов[Станция (остановка)],Справочник_станций_и_сборов[Расстояние от Мск (км)],)-_xlfn.XLOOKUP(Sales[[#This Row],[Станция ОТ]],Справочник_станций_и_сборов[Станция (остановка)],Справочник_станций_и_сборов[Расстояние от Мск (км)],))*Справочник!$Q$3+Справочник!$Q$2),"") | J29: =IFERROR(Sales[[#This Row],[Базовая цена, руб]] * _xlfn.XLOOKUP(Sales[[#This Row],[Тип пассажира]],Тип_пассажира[Наименование],Тип_пассажира[Цена]), "") | K29: =IFERROR(Sales[[#This Row],[Базовая цена, руб]] * VALUE(_xlfn.XLOOKUP(Sales[[#This Row],[Тип полки]], Тариф_полок[Тип полки], Тариф_полок[Коэф-нт цены], 1)),"") | L29: =IFERROR((Sales[[#This Row],[Базовая цена, руб]]-Sales[[#This Row],[Сумма скидки льготникам, руб]])-Sales[[#This Row],[Сумма скидки тип-места, руб2]],"") | N29: =IF(ISBLANK(P29),"","Свободно") -> Свободно | O29: =IF(ISBLANK(P29),"",IF(P29>36, IF(MOD(P29,2)=0, "Верхнее боковое место", "Нижнее боковое место"), IF(MOD(P29,2)=0, "Верхнее место", "Нижнее место"))) -> Нижнее боковое место | P29: 45 | Q29: =IFERROR(VLOOKUP(P29,Аналитика!A30:AH83,34,0),"") -> Частично | S29: Новочеркасск | T29: =VALUE(_xlfn.XLOOKUP(S29,Справочник_станций_и_сборов[Станция (остановка)],Справочник_станций_и_сборов[ID])) -> 28
